Workbook

Sheet Clienti
A1: id_client | B1: nume | C1: prenume | D1: CNP | E1: adresa | F1: telefon | J1: Verif. completitudine telefon | K1: Validitate CNP | L1: Validitate telefon
A2: 1 | B2: Popescu | C2: Ion | D2: 1234567890123 | E2: Strada Florilor 5 | F2: 0741123456 | J2: =IF(ISBLANK(F2),"Lipsă","OK") -> OK | K2: =IF(LEN(D2)=13,"OK","Invalid") -> OK | L2: =IF(LEN(F2)=10,"OK","Invalid") -> OK
A3: 2 | B3: Ionescu | C3: Maria | D3: 2234567890123 | E3: Strada Viilor 10 | F3: 0742123456 | J3: =IF(ISBLANK(F3),"Lipsă","OK") -> OK | K3: =IF(LEN(D3)=13,"OK","Invalid") -> OK | L3: =IF(LEN(F3)=10,"OK","Invalid") -> OK
A4: 3 | B4: Georgescu | C4: Andrei | D4: 3234567890123 | E4: Strada Ciresilor 15 | F4: 0743123456 | J4: =IF(ISBLANK(F4),"Lipsă","OK") -> OK | K4: =IF(LEN(D4)=13,"OK","Invalid") -> OK | L4: =IF(LEN(F4)=10,"OK","Invalid") -> OK
A5: 4 | B5: Dumitrescu | C5: Ana | D5: 4234567890123 | E5: Strada Salcamilor 20 | F5: 0744123456 | J5: =IF(ISBLANK(F5),"Lipsă","OK") -> OK | K5: =IF(LEN(D5)=13,"OK","Invalid") -> OK | L5: =IF(LEN(F5)=10,"OK","Invalid") -> OK
A6: 5 | B6: Vasilescu | C6: Mihai | D6: 5234567890123 | E6: Strada Castanilor 25 | F6: 0745123456 | J6: =IF(ISBLANK(F6),"Lipsă","OK") -> OK | K6: =IF(LEN(D6)=13,"OK","Invalid") -> OK | L6: =IF(LEN(F6)=10,"OK","Invalid") -> OK
A7: 6 | B7: Enescu | C7: Cristian | D7: 6234567890123 | E7: Strada Teiului 30 | F7: 0746123456 | J7: =IF(ISBLANK(F7),"Lipsă","OK") -> OK | K7: =IF(LEN(D7)=13,"OK","Invalid") -> OK | L7: =IF(LEN(F7)=10,"OK","Invalid") -> OK
A8: 7 | B8: Marin | C8: Elena | D8: 7234567890123 | E8: Strada Lalelelor 35 | F8: 0747123456 | J8: =IF(ISBLANK(F8),"Lipsă","OK") -> OK | K8: =IF(LEN(D8)=13,"OK","Invalid") -> OK | L8: =IF(LEN(F8)=10,"OK","Invalid") -> OK
A9: 8 | B9: Pavel | C9: Ioana | D9: 8234567890123 | E9: Strada Magnoliei 40 | F9: 0748123456 | J9: =IF(ISBLANK(F9),"Lipsă","OK") -> OK | K9: =IF(LEN(D9)=13,"OK","Invalid") -> OK | L9: =IF(LEN(F9)=10,"OK","Invalid") -> OK
A10: 9 | B10: Stan | C10: Adrian | D10: 9234567890123 | E10: Strada Fagului 45 | F10: 0749123456 | J10: =IF(ISBLANK(F10),"Lipsă","OK") -> OK | K10: =IF(LEN(D10)=13,"OK","Invalid") -> OK | L10: =IF(LEN(F10)=10,"OK","Invalid") -> OK
A11: 10 | B11: Drăgan | C11: Laura | D11: 1034567890123 | E11: Strada Paltinului 50 | F11: 0750123456 | J11: =IF(ISBLANK(F11),"Lipsă","OK") -> OK | K11: =IF(LEN(D11)=13,"OK","Invalid") -> OK | L11: =IF(LEN(F11)=10,"OK","Invalid") -> OK
A12: 11 | B12: Munteanu | C12: Victor | D12: 1134567890123 | E12: Strada Gorunului 55 | F12: 0751123456 | J12: =IF(ISBLANK(F12),"Lipsă","OK") -> OK | K12: =IF(LEN(D12)=13,"OK","Invalid") -> OK | L12: =IF(LEN(F12)=10,"OK","Invalid") -> OK
A13: 12 | B13: Bălan | C13: Simona | D13: 1234567890124 | E13: Strada Nucului 60 | F13: 0752123456 | J13: =IF(ISBLANK(F13),"Lipsă","OK") -> OK | K13: =IF(LEN(D13)=13,"OK","Invalid") -> OK | L13: =IF(LEN(F13)=10,"OK","Invalid") -> OK
... A101: 100 | B101: Petcu | C101: Elena | D101: 4361066528719 | E101: Strada Unirii 94 | F101: 0769730239 | J101: =IF(ISBLANK(F101),"Lipsă","OK") -> OK | K101: =IF(LEN(D101)=13,"OK","Invalid") -> OK | L101: =IF(LEN(F101)=10,"OK","Invalid") -> OK

Sheet Conturi
A1: id_cont | B1: id_client | C1: tip_cont | D1: sold | E1: data_crearii | G1: Verif. acuratețe sold | H1: Verif. completitudine id_client | K1: CheckData | M1: Consistență id_client
A2: 1001 | B2: 1 | C2: curent | D2: 1500.5 | E2: 44562 | G2: =IF(D2<0,"Greșit","OK") -> OK | H2: =IF(ISBLANK(B2),"Lipsă","OK") -> OK | K2: =IF(AND(E2>=DATE(2022,1,1),E2<=DATE(2023,12,31)),"OK","Outside") -> OK | M2: =IF(ISNA(VLOOKUP(B2,Clienti!A:A,1,FALSE)),"Lipsă","OK") -> OK
A3: 1002 | B3: 1 | C3: economii | D3: 5000.75 | E3: 44571 | G3: =IF(D3<0,"Greșit","OK") -> OK | H3: =IF(ISBLANK(B3),"Lipsă","OK") -> OK | K3: =IF(AND(E3>=DATE(2022,1,1),E3<=DATE(2023,12,31)),"OK","Outside") -> OK | M3: =IF(ISNA(VLOOKUP(B3,Clienti!A:A,1,FALSE)),"Lipsă","OK") -> OK
A4: 1003 | B4: 2 | C4: curent | D4: 1200 | E4: 44576 | G4: =IF(D4<0,"Greșit","OK") -> OK | H4: =IF(ISBLANK(B4),"Lipsă","OK") -> OK | K4: =IF(AND(E4>=DATE(2022,1,1),E4<=DATE(2023,12,31)),"OK","Outside") -> OK | M4: =IF(ISNA(VLOOKUP(B4,Clienti!A:A,1,FALSE)),"Lipsă","OK") -> OK
A5: 1004 | B5: 2 | C5: economii | D5: 3000 | E5: 44581 | G5: =IF(D5<0,"Greșit","OK") -> OK | H5: =IF(ISBLANK(B5),"Lipsă","OK") -> OK | K5: =IF(AND(E5>=DATE(2022,1,1),E5<=DATE(2023,12,31)),"OK","Outside") -> OK | M5: =IF(ISNA(VLOOKUP(B5,Clienti!A:A,1,FALSE)),"Lipsă","OK") -> OK
A6: 1005 | B6: 3 | C6: curent | D6: 4500.25 | E6: 44586 | G6: =IF(D6<0,"Greșit","OK") -> OK | H6: =IF(ISBLANK(B6),"Lipsă","OK") -> OK | K6: =IF(AND(E6>=DATE(2022,1,1),E6<=DATE(2023,12,31)),"OK","Outside") -> OK | M6: =IF(ISNA(VLOOKUP(B6,Clienti!A:A,1,FALSE)),"Lipsă","OK") -> OK
A7: 1006 | B7: 3 | C7: economii | D7: 7000 | E7: 44591 | G7: =IF(D7<0,"Greșit","OK") -> OK | H7: =IF(ISBLANK(B7),"Lipsă","OK") -> OK | K7: =IF(AND(E7>=DATE(2022,1,1),E7<=DATE(2023,12,31)),"OK","Outside") -> OK | M7: =IF(ISNA(VLOOKUP(B7,Clienti!A:A,1,FALSE)),"Lipsă","OK") -> OK
A8: 1007 | B8: 4 | C8: curent | D8: 2200.5 | E8: 44593 | G8: =IF(D8<0,"Greșit","OK") -> OK | H8: =IF(ISBLANK(B8),"Lipsă","OK") -> OK | K8: =IF(AND(E8>=DATE(2022,1,1),E8<=DATE(2023,12,31)),"OK","Outside") -> OK | M8: =IF(ISNA(VLOOKUP(B8,Clienti!A:A,1,FALSE)),"Lipsă","OK") -> OK
A9: 1008 | B9: 5 | C9: curent | D9: 3100.75 | E9: 44597 | G9: =IF(D9<0,"Greșit","OK") -> OK | H9: =IF(ISBLANK(B9),"Lipsă","OK") -> OK | K9: =IF(AND(E9>=DATE(2022,1,1),E9<=DATE(2023,12,31)),"OK","Outside") -> OK | M9: =IF(ISNA(VLOOKUP(B9,Clienti!A:A,1,FALSE)),"Lipsă","OK") -> OK
A10: 1009 | B10: 5 | C10: economii | D10: 8100.5 | E10: 44602 | G10: =IF(D10<0,"Greșit","OK") -> OK | H10: =IF(ISBLANK(B10),"Lipsă","OK") -> OK | K10: =IF(AND(E10>=DATE(2022,1,1),E10<=DATE(2023,12,31)),"OK","Outside") -> OK | M10: =IF(ISNA(VLOOKUP(B10,Clienti!A:A,1,FALSE)),"Lipsă","OK") -> OK
A11: 1010 | B11: 6 | C11: curent | D11: 4000 | E11: 44607 | G11: =IF(D11<0,"Greșit","OK") -> OK | H11: =IF(ISBLANK(B11),"Lipsă","OK") -> OK | K11: =IF(AND(E11>=DATE(2022,1,1),E11<=DATE(2023,12,31)),"OK","Outside") -> OK | M11: =IF(ISNA(VLOOKUP(B11,Clienti!A:A,1,FALSE)),"Lipsă","OK") -> OK
A12: 1011 | B12: 7 | C12: curent | D12: 3300.25 | E12: 44612 | G12: =IF(D12<0,"Greșit","OK") -> OK | H12: =IF(ISBLANK(B12),"Lipsă","OK") -> OK | K12: =IF(AND(E12>=DATE(2022,1,1),E12<=DATE(2023,12,31)),"OK","Outside") -> OK | M12: =IF(ISNA(VLOOKUP(B12,Clienti!A:A,1,FALSE)),"Lipsă","OK") -> OK
A13: 1012 | B13: 8 | C13: economii | D13: 9200 | E13: 44617 | G13: =IF(D13<0,"Greșit","OK") -> OK | H13: =IF(ISBLANK(B13),"Lipsă","OK") -> OK | K13: =IF(AND(E13>=DATE(2022,1,1),E13<=DATE(2023,12,31)),"OK","Outside") -> OK | M13: =IF(ISNA(VLOOKUP(B13,Clienti!A:A,1,FALSE)),"Lipsă","OK") -> OK
... A198: 1197 | B198: 100 | C198: economii | D198: 8416.35 | E198: 43901 | G198: =IF(D198<0,"Greșit","OK") -> OK | H198: =IF(ISBLANK(B198),"Lipsă","OK") -> OK | K198: =IF(AND(E198>=DATE(2022,1,1),E198<=DATE(2023,12,31)),"OK","Outside") -> Outside | M198: =IF(ISNA(VLOOKUP(B198,Clienti!A:A,1,FALSE)),"Lipsă","OK") -> OK

Sheet Tranzactii
A1: id_tranzactie | B1: id_cont_sursa | C1: id_cont_destinatie | D1: suma | E1: data_tranzactiei | F1: tip_tranzactie | I1: Verif. acuratețe tranzacție | J1: Verif. completitudine id_cont_destinatie | K1: Consistență id_cont_sursa | L1: Consistență id_cont_destinatie
A2: 16 | B2: 1001 | D2: 3586.6 | E2: 44863 | F2: retragere | I2: =IF(D2<0,"Greșit","OK") -> OK | J2: =IF(ISBLANK(C2),"Lipsă","OK") -> Lipsă | K2: =IF(ISNA(VLOOKUP(B2,Conturi!A:A,1,FALSE)),"Lipsă","OK") -> OK | L2: =IF(ISBLANK(C2),"Retragere sau depunere",IF(ISNA(VLOOKUP(C2,Conturi!A:A,1,FALSE)),"Lipsă","OK")) -> Retragere sau depunere
A3: 17 | B3: 1001 | C3: 1164 | D3: 3138.93 | E3: 44851 | F3: transfer | I3: =IF(D3<0,"Greșit","OK") -> OK | J3: =IF(ISBLANK(C3),"Lipsă","OK") -> OK | K3: =IF(ISNA(VLOOKUP(B3,Conturi!A:A,1,FALSE)),"Lipsă","OK") -> OK | L3: =IF(ISBLANK(C3),"Retragere sau depunere",IF(ISNA(VLOOKUP(C3,Conturi!A:A,1,FALSE)),"Lipsă","OK")) -> OK
A4: 18 | B4: 1002 | D4: 2391.68 | E4: 44783 | F4: retragere | I4: =IF(D4<0,"Greșit","OK") -> OK | J4: =IF(ISBLANK(C4),"Lipsă","OK") -> Lipsă | K4: =IF(ISNA(VLOOKUP(B4,Conturi!A:A,1,FALSE)),"Lipsă","OK") -> OK | L4: =IF(ISBLANK(C4),"Retragere sau depunere",IF(ISNA(VLOOKUP(C4,Conturi!A:A,1,FALSE)),"Lipsă","OK")) -> Retragere sau depunere
A5: 19 | B5: 1002 | D5: 341.64 | E5: 44852 | F5: retragere | I5: =IF(D5<0,"Greșit","OK") -> OK | J5: =IF(ISBLANK(C5),"Lipsă","OK") -> Lipsă | K5: =IF(ISNA(VLOOKUP(B5,Conturi!A:A,1,FALSE)),"Lipsă","OK") -> OK | L5: =IF(ISBLANK(C5),"Retragere sau depunere",IF(ISNA(VLOOKUP(C5,Conturi!A:A,1,FALSE)),"Lipsă","OK")) -> Retragere sau depunere
A6: 20 | B6: 1002 | D6: 3953.93 | E6: 44724 | F6: retragere | I6: =IF(D6<0,"Greșit","OK") -> OK | J6: =IF(ISBLANK(C6),"Lipsă","OK") -> Lipsă | K6: =IF(ISNA(VLOOKUP(B6,Conturi!A:A,1,FALSE)),"Lipsă","OK") -> OK | L6: =IF(ISBLANK(C6),"Retragere sau depunere",IF(ISNA(VLOOKUP(C6,Conturi!A:A,1,FALSE)),"Lipsă","OK")) -> Retragere sau depunere
A7: 21 | B7: 1002 | C7: 1173 | D7: 1012.6 | E7: 44892 | F7: transfer | I7: =IF(D7<0,"Greșit","OK") -> OK | J7: =IF(ISBLANK(C7),"Lipsă","OK") -> OK | K7: =IF(ISNA(VLOOKUP(B7,Conturi!A:A,1,FALSE)),"Lipsă","OK") -> OK | L7: =IF(ISBLANK(C7),"Retragere sau depunere",IF(ISNA(VLOOKUP(C7,Conturi!A:A,1,FALSE)),"Lipsă","OK")) -> OK
A8: 22 | B8: 1003 | D8: 1938.01 | E8: 44872 | F8: depunere | I8: =IF(D8<0,"Greșit","OK") -> OK | J8: =IF(ISBLANK(C8),"Lipsă","OK") -> Lipsă | K8: =IF(ISNA(VLOOKUP(B8,Conturi!A:A,1,FALSE)),"Lipsă","OK") -> OK | L8: =IF(ISBLANK(C8),"Retragere sau depunere",IF(ISNA(VLOOKUP(C8,Conturi!A:A,1,FALSE)),"Lipsă","OK")) -> Retragere sau depunere
A9: 23 | B9: 1003 | D9: 3568.43 | E9: 44884 | F9: retragere | I9: =IF(D9<0,"Greșit","OK") -> OK | J9: =IF(ISBLANK(C9),"Lipsă","OK") -> Lipsă | K9: =IF(ISNA(VLOOKUP(B9,Conturi!A:A,1,FALSE)),"Lipsă","OK") -> OK | L9: =IF(ISBLANK(C9),"Retragere sau depunere",IF(ISNA(VLOOKUP(C9,Conturi!A:A,1,FALSE)),"Lipsă","OK")) -> Retragere sau depunere
A10: 24 | B10: 1003 | D10: 3214.61 | E10: 44776 | F10: retragere | I10: =IF(D10<0,"Greșit","OK") -> OK | J10: =IF(ISBLANK(C10),"Lipsă","OK") -> Lipsă | K10: =IF(ISNA(VLOOKUP(B10,Conturi!A:A,1,FALSE)),"Lipsă","OK") -> OK | L10: =IF(ISBLANK(C10),"Retragere sau depunere",IF(ISNA(VLOOKUP(C10,Conturi!A:A,1,FALSE)),"Lipsă","OK")) -> Retragere sau depunere
A11: 25 | B11: 1004 | C11: 1166 | D11: 4123.69 | E11: 44625 | F11: transfer | I11: =IF(D11<0,"Greșit","OK") -> OK | J11: =IF(ISBLANK(C11),"Lipsă","OK") -> OK | K11: =IF(ISNA(VLOOKUP(B11,Conturi!A:A,1,FALSE)),"Lipsă","OK") -> OK | L11: =IF(ISBLANK(C11),"Retragere sau depunere",IF(ISNA(VLOOKUP(C11,Conturi!A:A,1,FALSE)),"Lipsă","OK")) -> OK
A12: 26 | B12: 1004 | D12: 3876.02 | E12: 44675 | F12: depunere | I12: =IF(D12<0,"Greșit","OK") -> OK | J12: =IF(ISBLANK(C12),"Lipsă","OK") -> Lipsă | K12: =IF(ISNA(VLOOKUP(B12,Conturi!A:A,1,FALSE)),"Lipsă","OK") -> OK | L12: =IF(ISBLANK(C12),"Retragere sau depunere",IF(ISNA(VLOOKUP(C12,Conturi!A:A,1,FALSE)),"Lipsă","OK")) -> Retragere sau depunere
A13: 27 | B13: 1004 | C13: 1123 | D13: 2598.8 | E13: 44914 | F13: transfer | I13: =IF(D13<0,"Greșit","OK") -> OK | J13: =IF(ISBLANK(C13),"Lipsă","OK") -> OK | K13: =IF(ISNA(VLOOKUP(B13,Conturi!A:A,1,FALSE)),"Lipsă","OK") -> OK | L13: =IF(ISBLANK(C13),"Retragere sau depunere",IF(ISNA(VLOOKUP(C13,Conturi!A:A,1,FALSE)),"Lipsă","OK")) -> OK
A14: 28 | B14: 1004 | D14: 2497.72 | E14: 44786 | F14: depunere | I14: =IF(D14<0,"Greșit","OK") -> OK | J14: =IF(ISBLANK(C14),"Lipsă","OK") -> Lipsă | K14: =IF(ISNA(VLOOKUP(B14,Conturi!A:A,1,FALSE)),"Lipsă","OK") -> OK | L14: =IF(ISBLANK(C14),"Retragere sau depunere",IF(ISNA(VLOOKUP(C14,Conturi!A:A,1,FALSE)),"Lipsă","OK")) -> Retragere sau depunere
A15: 29 | B15: 1005 | D15: 374.46 | E15: 44593 | F15: depunere | I15: =IF(D15<0,"Greșit","OK") -> OK | J15: =IF(ISBLANK(C15),"Lipsă","OK") -> Lipsă | K15: =IF(ISNA(VLOOKUP(B15,Conturi!A:A,1,FALSE)),"Lipsă","OK") -> OK | L15: =IF(ISBLANK(C15),"Retragere sau depunere",IF(ISNA(VLOOKUP(C15,Conturi!A:A,1,FALSE)),"Lipsă","OK")) -> Retragere sau depunere
A16: 30 | B16: 1005 | C16: 1102 | D16: 1553.21 | E16: 44618 | F16: transfer | I16: =IF(D16<0,"Greșit","OK") -> OK | J16: =IF(ISBLANK(C16),"Lipsă","OK") -> OK | K16: =IF(ISNA(VLOOKUP(B16,Conturi!A:A,1,FALSE)),"Lipsă","OK") -> OK | L16: =IF(ISBLANK(C16),"Retragere sau depunere",IF(ISNA(VLOOKUP(C16,Conturi!A:A,1,FALSE)),"Lipsă","OK")) -> OK
A17: 31 | B17: 1005 | C17: 1194 | D17: 2855.63 | E17: 44887 | F17: transfer | I17: =IF(D17<0,"Greșit","OK") -> OK | J17: =IF(ISBLANK(C17),"Lipsă","OK") -> OK | K17: =IF(ISNA(VLOOKUP(B17,Conturi!A:A,1,FALSE)),"Lipsă","OK") -> OK | L17: =IF(ISBLANK(C17),"Retragere sau depunere",IF(ISNA(VLOOKUP(C17,Conturi!A:A,1,FALSE)),"Lipsă","OK")) -> OK
A18: 32 | B18: 1005 | C18: 1021 | D18: 4578.99 | E18: 44870 | F18: transfer | I18: =IF(D18<0,"Greșit","OK") -> OK | J18: =IF(ISBLANK(C18),"Lipsă","OK") -> OK | K18: =IF(ISNA(VLOOKUP(B18,Conturi!A:A,1,FALSE)),"Lipsă","OK") -> OK | L18: =IF(ISBLANK(C18),"Retragere sau depunere",IF(ISNA(VLOOKUP(C18,Conturi!A:A,1,FALSE)),"Lipsă","OK")) -> OK
A19: 33 | B19: 1006 | D19: 3179.09 | E19: 44868 | F19: retragere | I19: =IF(D19<0,"Greșit","OK") -> OK | J19: =IF(ISBLANK(C19),"Lipsă","OK") -> Lipsă | K19: =IF(ISNA(VLOOKUP(B19,Conturi!A:A,1,FALSE)),"Lipsă","OK") -> OK | L19: =IF(ISBLANK(C19),"Retragere sau depunere",IF(ISNA(VLOOKUP(C19,Conturi!A:A,1,FALSE)),"Lipsă","OK")) -> Retragere sau depunere
A20: 34 | B20: 1006 | D20: 2303.26 | E20: 44638 | F20: retragere | I20: =IF(D20<0,"Greșit","OK") -> OK | J20: =IF(ISBLANK(C20),"Lipsă","OK") -> Lipsă | K20: =IF(ISNA(VLOOKUP(B20,Conturi!A:A,1,FALSE)),"Lipsă","OK") -> OK | L20: =IF(ISBLANK(C20),"Retragere sau depunere",IF(ISNA(VLOOKUP(C20,Conturi!A:A,1,FALSE)),"Lipsă","OK")) -> Retragere sau depunere
A21: 35 | B21: 1006 | D21: 4936.95 | E21: 44570 | F21: retragere | I21: =IF(D21<0,"Greșit","OK") -> OK | J21: =IF(ISBLANK(C21),"Lipsă","OK") -> Lipsă | K21: =IF(ISNA(VLOOKUP(B21,Conturi!A:A,1,FALSE)),"Lipsă","OK") -> OK | L21: =IF(ISBLANK(C21),"Retragere sau depunere",IF(ISNA(VLOOKUP(C21,Conturi!A:A,1,FALSE)),"Lipsă","OK")) -> Retragere sau depunere
A22: 36 | B22: 1007 | C22: 1071 | D22: 815.24 | E22: 44752 | F22: transfer | I22: =IF(D22<0,"Greșit","OK") -> OK | J22: =IF(ISBLANK(C22),"Lipsă","OK") -> OK | K22: =IF(ISNA(VLOOKUP(B22,Conturi!A:A,1,FALSE)),"Lipsă","OK") -> OK | L22: =IF(ISBLANK(C22),"Retragere sau depunere",IF(ISNA(VLOOKUP(C22,Conturi!A:A,1,FALSE)),"Lipsă","OK")) -> OK
A23: 37 | B23: 1007 | D23: 4548.41 | E23: 44593 | F23: retragere | I23: =IF(D23<0,"Greșit","OK") -> OK | J23: =IF(ISBLANK(C23),"Lipsă","OK") -> Lipsă | K23: =IF(ISNA(VLOOKUP(B23,Conturi!A:A,1,FALSE)),"Lipsă","OK") -> OK | L23: =IF(ISBLANK(C23),"Retragere sau depunere",IF(ISNA(VLOOKUP(C23,Conturi!A:A,1,FALSE)),"Lipsă","OK")) -> Retragere sau depunere
A24: 38 | B24: 1008 | D24: 648.63 | E24: 44726 | F24: retragere | I24: =IF(D24<0,"Greșit","OK") -> OK | J24: =IF(ISBLANK(C24),"Lipsă","OK") -> Lipsă | K24: =IF(ISNA(VLOOKUP(B24,Conturi!A:A,1,FALSE)),"Lipsă","OK") -> OK | L24: =IF(ISBLANK(C24),"Retragere sau depunere",IF(ISNA(VLOOKUP(C24,Conturi!A:A,1,FALSE)),"Lipsă","OK")) -> Retragere sau depunere
A25: 39 | B25: 1008 | D25: 473.67 | E25: 44876 | F25: depunere | I25: =IF(D25<0,"Greșit","OK") -> OK | J25: =IF(ISBLANK(C25),"Lipsă","OK") -> Lipsă | K25: =IF(ISNA(VLOOKUP(B25,Conturi!A:A,1,FALSE)),"Lipsă","OK") -> OK | L25: =IF(ISBLANK(C25),"Retragere sau depunere",IF(ISNA(VLOOKUP(C25,Conturi!A:A,1,FALSE)),"Lipsă","OK")) -> Retragere sau depunere
A26: 40 | B26: 1009 | D26: 2700.94 | E26: 44854 | F26: depunere | I26: =IF(D26<0,"Greșit","OK") -> OK | J26: =IF(ISBLANK(C26),"Lipsă","OK") -> Lipsă | K26: =IF(ISNA(VLOOKUP(B26,Conturi!A:A,1,FALSE)),"Lipsă","OK") -> OK | L26: =IF(ISBLANK(C26),"Retragere sau depunere",IF(ISNA(VLOOKUP(C26,Conturi!A:A,1,FALSE)),"Lipsă","OK")) -> Retragere sau depunere
A27: 41 | B27: 1009 | C27: 1012 | D27: 3393.6 | E27: 44717 | F27: transfer | I27: =IF(D27<0,"Greșit","OK") -> OK | J27: =IF(ISBLANK(C27),"Lipsă","OK") -> OK | K27: =IF(ISNA(VLOOKUP(B27,Conturi!A:A,1,FALSE)),"Lipsă","OK") -> OK | L27: =IF(ISBLANK(C27),"Retragere sau depunere",IF(ISNA(VLOOKUP(C27,Conturi!A:A,1,FALSE)),"Lipsă","OK")) -> OK
A28: 42 | B28: 1009 | D28: 1810.23 | E28: 44573 | F28: depunere | I28: =IF(D28<0,"Greșit","OK") -> OK | J28: =IF(ISBLANK(C28),"Lipsă","OK") -> Lipsă | K28: =IF(ISNA(VLOOKUP(B28,Conturi!A:A,1,FALSE)),"Lipsă","OK") -> OK | L28: =IF(ISBLANK(C28),"Retragere sau depunere",IF(ISNA(VLOOKUP(C28,Conturi!A:A,1,FALSE)),"Lipsă","OK")) -> Retragere sau depunere
A29: 43 | B29: 1009 | C29: 1085 | D29: 4110.69 | E29: 44775 | F29: transfer | I29: =IF(D29<0,"Greșit","OK") -> OK | J29: =IF(ISBLANK(C29),"Lipsă","OK") -> OK | K29: =IF(ISNA(VLOOKUP(B29,Conturi!A:A,1,FALSE)),"Lipsă","OK") -> OK | L29: =IF(ISBLANK(C29),"Retragere sau depunere",IF(ISNA(VLOOKUP(C29,Conturi!A:A,1,FALSE)),"Lipsă","OK")) -> OK
A30: 44 | B30: 1010 | D30: 1048.14 | E30: 44594 | F30: retragere | I30: =IF(D30<0,"Greșit","OK") -> OK | J30: =IF(ISBLANK(C30),"Lipsă","OK") -> Lipsă | K30: =IF(ISNA(VLOOKUP(B30,Conturi!A:A,1,FALSE)),"Lipsă","OK") -> OK | L30: =IF(ISBLANK(C30),"Retragere sau depunere",IF(ISNA(VLOOKUP(C30,Conturi!A:A,1,FALSE)),"Lipsă","OK")) -> Retragere sau depunere
A31: 45 | B31: 1010 | D31: 1136.53 | E31: 44924 | F31: retragere | I31: =IF(D31<0,"Greșit","OK") -> OK | J31: =IF(ISBLANK(C31),"Lipsă","OK") -> Lipsă | K31: =IF(ISNA(VLOOKUP(B31,Conturi!A:A,1,FALSE)),"Lipsă","OK") -> OK | L31: =IF(ISBLANK(C31),"Retragere sau depunere",IF(ISNA(VLOOKUP(C31,Conturi!A:A,1,FALSE)),"Lipsă","OK")) -> Retragere sau depunere
A32: 46 | B32: 1010 | D32: 1678.89 | E32: 44703 | F32: depunere | I32: =IF(D32<0,"Greșit","OK") -> OK | J32: =IF(ISBLANK(C32),"Lipsă","OK") -> Lipsă | K32: =IF(ISNA(VLOOKUP(B32,Conturi!A:A,1,FALSE)),"Lipsă","OK") -> OK | L32: =IF(ISBLANK(C32),"Retragere sau depunere",IF(ISNA(VLOOKUP(C32,Conturi!A:A,1,FALSE)),"Lipsă","OK")) -> Retragere sau depunere
A33: 47 | B33: 1010 | C33: 1023 | D33: 2894.07 | E33: 44709 | F33: transfer | I33: =IF(D33<0,"Greșit","OK") -> OK | J33: =IF(ISBLANK(C33),"Lipsă","OK") -> OK | K33: =IF(ISNA(VLOOKUP(B33,Conturi!A:A,1,FALSE)),"Lipsă","OK") -> OK | L33: =IF(ISBLANK(C33),"Retragere sau depunere",IF(ISNA(VLOOKUP(C33,Conturi!A:A,1,FALSE)),"Lipsă","OK")) -> OK
A34: 48 | B34: 1010 | C34: 1112 | D34: 308.23 | E34: 44725 | F34: transfer | I34: =IF(D34<0,"Greșit","OK") -> OK | J34: =IF(ISBLANK(C34),"Lipsă","OK") -> OK | K34: =IF(ISNA(VLOOKUP(B34,Conturi!A:A,1,FALSE)),"Lipsă","OK") -> OK | L34: =IF(ISBLANK(C34),"Retragere sau depunere",IF(ISNA(VLOOKUP(C34,Conturi!A:A,1,FALSE)),"Lipsă","OK")) -> OK
A35: 49 | B35: 1011 | D35: 1553.44 | E35: 44654 | F35: depunere | I35: =IF(D35<0,"Greșit","OK") -> OK | J35: =IF(ISBLANK(C35),"Lipsă","OK") -> Lipsă | K35: =IF(ISNA(VLOOKUP(B35,Conturi!A:A,1,FALSE)),"Lipsă","OK") -> OK | L35: =IF(ISBLANK(C35),"Retragere sau depunere",IF(ISNA(VLOOKUP(C35,Conturi!A:A,1,FALSE)),"Lipsă","OK")) -> Retragere sau depunere
A36: 50 | B36: 1011 | D36: 681.61 | E36: 44731 | F36: retragere | I36: =IF(D36<0,"Greșit","OK") -> OK | J36: =IF(ISBLANK(C36),"Lipsă","OK") -> Lipsă | K36: =IF(ISNA(VLOOKUP(B36,Conturi!A:A,1,FALSE)),"Lipsă","OK") -> OK | L36: =IF(ISBLANK(C36),"Retragere sau depunere",IF(ISNA(VLOOKUP(C36,Conturi!A:A,1,FALSE)),"Lipsă","OK")) -> Retragere sau depunere
A37: 51 | B37: 1011 | D37: 4684.61 | E37: 44731 | F37: retragere | I37: =IF(D37<0,"Greșit","OK") -> OK | J37: =IF(ISBLANK(C37),"Lipsă","OK") -> Lipsă | K37: =IF(ISNA(VLOOKUP(B37,Conturi!A:A,1,FALSE)),"Lipsă","OK") -> OK | L37: =IF(ISBLANK(C37),"Retragere sau depunere",IF(ISNA(VLOOKUP(C37,Conturi!A:A,1,FALSE)),"Lipsă","OK")) -> Retragere sau depunere
A38: 52 | B38: 1012 | C38: 1139 | D38: 1378.35 | E38: 44829 | F38: transfer | I38: =IF(D38<0,"Greșit","OK") -> OK | J38: =IF(ISBLANK(C38),"Lipsă","OK") -> OK | K38: =IF(ISNA(VLOOKUP(B38,Conturi!A:A,1,FALSE)),"Lipsă","OK") -> OK | L38: =IF(ISBLANK(C38),"Retragere sau depunere",IF(ISNA(VLOOKUP(C38,Conturi!A:A,1,FALSE)),"Lipsă","OK")) -> OK
A39: 53 | B39: 1013 | D39: 1887.52 | E39: 44885 | F39: depunere | I39: =IF(D39<0,"Greșit","OK") -> OK | J39: =IF(ISBLANK(C39),"Lipsă","OK") -> Lipsă | K39: =IF(ISNA(VLOOKUP(B39,Conturi!A:A,1,FALSE)),"Lipsă","OK") -> OK | L39: =IF(ISBLANK(C39),"Retragere sau depunere",IF(ISNA(VLOOKUP(C39,Conturi!A:A,1,FALSE)),"Lipsă","OK")) -> Retragere sau depunere
A40: 54 | B40: 1013 | D40: 3974.45 | E40: 44891 | F40: depunere | I40: =IF(D40<0,"Greșit","OK") -> OK | J40: =IF(ISBLANK(C40),"Lipsă","OK") -> Lipsă | K40: =IF(ISNA(VLOOKUP(B40,Conturi!A:A,1,FALSE)),"Lipsă","OK") -> OK | L40: =IF(ISBLANK(C40),"Retragere sau depunere",IF(ISNA(VLOOKUP(C40,Conturi!A:A,1,FALSE)),"Lipsă","OK")) -> Retragere sau depunere
...

Sheet Carduri
A1: id_card | B1: id_cont | C1: numar_card | D1: data_expirare | E1: cvv | H1: Verificare completitudine cvv | I1: Validitate număr card | J1: Validitate cvv
A2: 2016 | B2: 1001 | C2: 2121392385263234 | D2: 47485.788 | E2: 858 | H2: =IF(ISBLANK(E2),"Lipsă","OK") -> OK | I2: =IF(LEN(C2)=16,"OK","Invalid") -> OK | J2: =IF(LEN(E2)=3,"OK","Invalid") -> OK
A3: 2017 | B3: 1002 | C3: 6249509041245919 | D3: 47120.788 | E3: 577 | H3: =IF(ISBLANK(E3),"Lipsă","OK") -> OK | I3: =IF(LEN(C3)=16,"OK","Invalid") -> OK | J3: =IF(LEN(E3)=3,"OK","Invalid") -> OK
A4: 2018 | B4: 1002 | C4: 7795388068345444 | D4: 47485.788 | E4: 938 | H4: =IF(ISBLANK(E4),"Lipsă","OK") -> OK | I4: =IF(LEN(C4)=16,"OK","Invalid") -> OK | J4: =IF(LEN(E4)=3,"OK","Invalid") -> OK
A5: 2019 | B5: 1003 | C5: 9602307451897598 | D5: 47485.788 | E5: 651 | H5: =IF(ISBLANK(E5),"Lipsă","OK") -> OK | I5: =IF(LEN(C5)=16,"OK","Invalid") -> OK | J5: =IF(LEN(E5)=3,"OK","Invalid") -> OK
A6: 2020 | B6: 1004 | C6: 6368187287013810 | D6: 47120.788 | E6: 558 | H6: =IF(ISBLANK(E6),"Lipsă","OK") -> OK | I6: =IF(LEN(C6)=16,"OK","Invalid") -> OK | J6: =IF(LEN(E6)=3,"OK","Invalid") -> OK
A7: 2021 | B7: 1005 | C7: 5411410025698213 | D7: 47850.788 | E7: 184 | H7: =IF(ISBLANK(E7),"Lipsă","OK") -> OK | I7: =IF(LEN(C7)=16,"OK","Invalid") -> OK | J7: =IF(LEN(E7)=3,"OK","Invalid") -> OK
A8: 2022 | B8: 1006 | C8: 5551029323095116 | D8: 46390.788 | E8: 572 | H8: =IF(ISBLANK(E8),"Lipsă","OK") -> OK | I8: =IF(LEN(C8)=16,"OK","Invalid") -> OK | J8: =IF(LEN(E8)=3,"OK","Invalid") -> OK
A9: 2023 | B9: 1006 | C9: 3819493489901617 | D9: 46390.788 | E9: 963 | H9: =IF(ISBLANK(E9),"Lipsă","OK") -> OK | I9: =IF(LEN(C9)=16,"OK","Invalid") -> OK | J9: =IF(LEN(E9)=3,"OK","Invalid") -> OK
A10: 2024 | B10: 1007 | C10: 4612471941433031 | D10: 47485.788 | E10: 269 | H10: =IF(ISBLANK(E10),"Lipsă","OK") -> OK | I10: =IF(LEN(C10)=16,"OK","Invalid") -> OK | J10: =IF(LEN(E10)=3,"OK","Invalid") -> OK
A11: 2025 | B11: 1008 | C11: 9877593008156561 | D11: 47850.788 | E11: 813 | H11: =IF(ISBLANK(E11),"Lipsă","OK") -> OK | I11: =IF(LEN(C11)=16,"OK","Invalid") -> OK | J11: =IF(LEN(E11)=3,"OK","Invalid") -> OK
A12: 2026 | B12: 1008 | C12: 6392955627630152 | D12: 47485.788 | E12: 293 | H12: =IF(ISBLANK(E12),"Lipsă","OK") -> OK | I12: =IF(LEN(C12)=16,"OK","Invalid") -> OK | J12: =IF(LEN(E12)=3,"OK","Invalid") -> OK
A13: 2027 | B13: 1009 | C13: 8855263853222602 | D13: 47850.788 | E13: 799 | H13: =IF(ISBLANK(E13),"Lipsă","OK") -> OK | I13: =IF(LEN(C13)=16,"OK","Invalid") -> OK | J13: =IF(LEN(E13)=3,"OK","Invalid") -> OK
... A286: 2300 | B286: 1197 | C286: 6054769265390559 | D286: 47485.788 | E286: 509 | H286: =IF(ISBLANK(E286),"Lipsă","OK") -> OK | I286: =IF(LEN(C286)=16,"OK","Invalid") -> OK | J286: =IF(LEN(E286)=3,"OK","Invalid") -> OK

Sheet Credite
A1: id_credit | B1: id_client | C1: suma_credit | D1: rata_lunara | E1: data_acordarii | F1: data_scadentei | J1: Verificare acuratețe rată lunară | L1: Verificare acuratețe data scandenței | M1: Consistență id_client
A2: 16 | B2: 1 | C2: 32875.4 | D2: 1643.77 | E2: 44595 | F2: 45195 | J2: =IF(D2<0,"Greșit","OK") -> OK | L2: =IF(F2>=E2,"OK","Greșit") -> OK | M2: =IF(ISNA(VLOOKUP(B2,Clienti!A:A,1,FALSE)),"Lipsă","OK") -> OK
A3: 17 | B3: 2 | C3: 30066.74 | D3: 812.61 | E3: 44653 | F3: 45763 | J3: =IF(D3<0,"Greșit","OK") -> OK | L3: =IF(F3>=E3,"OK","Greșit") -> OK | M3: =IF(ISNA(VLOOKUP(B3,Clienti!A:A,1,FALSE)),"Lipsă","OK") -> OK
A4: 18 | B4: 4 | C4: 9578.68 | D4: 532.15 | E4: 44821 | F4: 45361 | J4: =IF(D4<0,"Greșit","OK") -> OK | L4: =IF(F4>=E4,"OK","Greșit") -> OK | M4: =IF(ISNA(VLOOKUP(B4,Clienti!A:A,1,FALSE)),"Lipsă","OK") -> OK
A5: 19 | B5: 4 | C5: 15427.74 | D5: 964.23 | E5: 44591 | F5: 45071 | J5: =IF(D5<0,"Greșit","OK") -> OK | L5: =IF(F5>=E5,"OK","Greșit") -> OK | M5: =IF(ISNA(VLOOKUP(B5,Clienti!A:A,1,FALSE)),"Lipsă","OK") -> OK
A6: 20 | B6: 6 | C6: 6379.55 | D6: 115.99 | E6: 44651 | F6: 46301 | J6: =IF(D6<0,"Greșit","OK") -> OK | L6: =IF(F6>=E6,"OK","Greșit") -> OK | M6: =IF(ISNA(VLOOKUP(B6,Clienti!A:A,1,FALSE)),"Lipsă","OK") -> OK
A7: 21 | B7: 6 | C7: 4190.06 | D7: 71.02 | E7: 44581 | F7: 46351 | J7: =IF(D7<0,"Greșit","OK") -> OK | L7: =IF(F7>=E7,"OK","Greșit") -> OK | M7: =IF(ISNA(VLOOKUP(B7,Clienti!A:A,1,FALSE)),"Lipsă","OK") -> OK
A8: 22 | B8: 6 | C8: 10285.63 | D8: 270.67 | E8: 44846 | F8: 45986 | J8: =IF(D8<0,"Greșit","OK") -> OK | L8: =IF(F8>=E8,"OK","Greșit") -> OK | M8: =IF(ISNA(VLOOKUP(B8,Clienti!A:A,1,FALSE)),"Lipsă","OK") -> OK
A9: 23 | B9: 7 | C9: 35541.91 | D9: 1269.35 | E9: 44890 | F9: 45730 | J9: =IF(D9<0,"Greșit","OK") -> OK | L9: =IF(F9>=E9,"OK","Greșit") -> OK | M9: =IF(ISNA(VLOOKUP(B9,Clienti!A:A,1,FALSE)),"Lipsă","OK") -> OK
A10: 24 | B10: 9 | C10: 6749.45 | D10: 114.4 | E10: 44625 | F10: 46395 | J10: =IF(D10<0,"Greșit","OK") -> OK | L10: =IF(F10>=E10,"OK","Greșit") -> OK | M10: =IF(ISNA(VLOOKUP(B10,Clienti!A:A,1,FALSE)),"Lipsă","OK") -> OK
A11: 25 | B11: 9 | C11: 40572.61 | D11: 3120.97 | E11: 44584 | F11: 44974 | J11: =IF(D11<0,"Greșit","OK") -> OK | L11: =IF(F11>=E11,"OK","Greșit") -> OK | M11: =IF(ISNA(VLOOKUP(B11,Clienti!A:A,1,FALSE)),"Lipsă","OK") -> OK
A12: 26 | B12: 9 | C12: 1025.07 | D12: 19.71 | E12: 44691 | F12: 46251 | J12: =IF(D12<0,"Greșit","OK") -> OK | L12: =IF(F12>=E12,"OK","Greșit") -> OK | M12: =IF(ISNA(VLOOKUP(B12,Clienti!A:A,1,FALSE)),"Lipsă","OK") -> OK
A13: 27 | B13: 12 | C13: 7018.97 | D13: 123.14 | E13: 44618 | F13: 46328 | J13: =IF(D13<0,"Greșit","OK") -> OK | L13: =IF(F13>=E13,"OK","Greșit") -> OK | M13: =IF(ISNA(VLOOKUP(B13,Clienti!A:A,1,FALSE)),"Lipsă","OK") -> OK
... A139: 153 | B139: 100 | C139: 39108.3 | D139: 2607.22 | E139: 44562 | F139: 45012 | J139: =IF(D139<0,"Greșit","OK") -> OK | L139: =IF(F139>=E139,"OK","Greșit") -> OK | M139: =IF(ISNA(VLOOKUP(B139,Clienti!A:A,1,FALSE)),"Lipsă","OK") -> OK

Sheet Analiză descriptivă
A1: id_client | B1: sold | C1: tip_cont | D1: Verif. OUTLIER | E1: min sold = | F1: =MIN(B2:B198) -> 374.95 | J1: id_tranzactie | K1: suma | L1: tip_tranzactie | M1: Verif. OUTLIER | N1: min tranzacție = | O1: =MIN(K2:K593) -> 13.97 | R1: id_client | S1: id_credit | T1: suma_credit | U1: rata_lunara | V1: Verif. OUTLIER sumă_credit | W1: Verif. OUTLIER rată | Y1: min sumă credit = | Z1: =MIN(T2:T139) -> 1025.07
A2: 1 | B2: 1500.5 | C2: curent | D2: =IF(OR(B2<$F$9,B2>$F$10),"Outlier","În interval") -> În interval | E2: max sold = | F2: =MAX(B2:B198) -> 49576.77 | J2: 16 | K2: 3586.6 | L2: retragere | M2: =IF(OR(K2<$O$9,K2>$O$10),"Outlier","În interval") -> În interval | N2: max tranzacție = | O2: =MAX(K2:K593) -> 4988.33 | R2: 1 | S2: 16 | T2: 32875.4 | U2: 1643.77 | V2: =IF(OR(T2<$Z$9,T2>$Z$10),"Outlier","În interval") -> În interval | W2: =IF(OR(U2<$Z$22,U2>$Z$23),"Outlier","În interval") -> În interval | Y2: max sumă credit = | Z2: =MAX(T2:T139) -> 49703.15
A3: 1 | B3: 5000.75 | C3: economii | D3: =IF(OR(B3<$F$9,B3>$F$10),"Outlier","În interval") -> În interval | E3: media sold = | F3: =AVERAGE(B2:B198) -> 22978.211 | J3: 17 | K3: 3138.93 | L3: transfer | M3: =IF(OR(K3<$O$9,K3>$O$10),"Outlier","În interval") -> În interval | N3: media tranz. = | O3: =AVERAGE(K2:K593) -> 2539.7449 | R3: 2 | S3: 17 | T3: 30066.74 | U3: 812.61 | V3: =IF(OR(T3<$Z$9,T3>$Z$10),"Outlier","În interval") -> În interval | W3: =IF(OR(U3<$Z$22,U3>$Z$23),"Outlier","În interval") -> În interval | Y3: media sumă credit = | Z3: =AVERAGE(T2:T139) -> 24876.358
A4: 2 | B4: 1200 | C4: curent | D4: =IF(OR(B4<$F$9,B4>$F$10),"Outlier","În interval") -> În interval | E4: mediana sold = | F4: =MEDIAN(B2:B198) -> 22383.01 | J4: 18 | K4: 2391.68 | L4: retragere | M4: =IF(OR(K4<$O$9,K4>$O$10),"Outlier","În interval") -> În interval | N4: mediana tranz. = | O4: =MEDIAN(K2:K593) -> 2509.305 | R4: 4 | S4: 18 | T4: 9578.68 | U4: 532.15 | V4: =IF(OR(T4<$Z$9,T4>$Z$10),"Outlier","În interval") -> În interval | W4: =IF(OR(U4<$Z$22,U4>$Z$23),"Outlier","În interval") -> În interval | Y4: mediana sumă credit = | Z4: =MEDIAN(T2:T139) -> 25030.06
A5: 2 | B5: 3000 | C5: economii | D5: =IF(OR(B5<$F$9,B5>$F$10),"Outlier","În interval") -> În interval | E5: sd sold = | F5: =STDEV(B2:B198) -> 15183.694 | J5: 19 | K5: 341.64 | L5: retragere | M5: =IF(OR(K5<$O$9,K5>$O$10),"Outlier","În interval") -> În interval | N5: sd tranz. = | O5: =STDEV(K2:K593) -> 1428.3295 | R5: 4 | S5: 19 | T5: 15427.74 | U5: 964.23 | V5: =IF(OR(T5<$Z$9,T5>$Z$10),"Outlier","În interval") -> În interval | W5: =IF(OR(U5<$Z$22,U5>$Z$23),"Outlier","În interval") -> În interval | Y5: sd. sumă credit = | Z5: =STDEV(T2:T139) -> 14069.623
A6: 3 | B6: 4500.25 | C6: curent | D6: =IF(OR(B6<$F$9,B6>$F$10),"Outlier","În interval") -> În interval | E6: Q1 = | F6: =QUARTILE(B2:B198,1) -> 9207.06 | J6: 20 | K6: 3953.93 | L6: retragere | M6: =IF(OR(K6<$O$9,K6>$O$10),"Outlier","În interval") -> În interval | N6: Q1 = | O6: =QUARTILE(K2:K593,1) -> 1297.42 | R6: 6 | S6: 20 | T6: 6379.55 | U6: 115.99 | V6: =IF(OR(T6<$Z$9,T6>$Z$10),"Outlier","În interval") -> În interval | W6: =IF(OR(U6<$Z$22,U6>$Z$23),"Outlier","În interval") -> În interval | Y6: Q1 = | Z6: =QUARTILE(T2:T139,1) -> 12525.6
A7: 3 | B7: 7000 | C7: economii | D7: =IF(OR(B7<$F$9,B7>$F$10),"Outlier","În interval") -> În interval | E7: Q3 = | F7: =QUARTILE(B2:B198,3) -> 34800.41 | J7: 21 | K7: 1012.6 | L7: transfer | M7: =IF(OR(K7<$O$9,K7>$O$10),"Outlier","În interval") -> În interval | N7: Q3 = | O7: =QUARTILE(K2:K593,3) -> 3754.215 | R7: 6 | S7: 21 | T7: 4190.06 | U7: 71.02 | V7: =IF(OR(T7<$Z$9,T7>$Z$10),"Outlier","În interval") -> În interval | W7: =IF(OR(U7<$Z$22,U7>$Z$23),"Outlier","În interval") -> În interval | Y7: Q3 = | Z7: =QUARTILE(T2:T139,3) -> 35330.202
A8: 4 | B8: 2200.5 | C8: curent | D8: =IF(OR(B8<$F$9,B8>$F$10),"Outlier","În interval") -> În interval | E8: IQR = | F8: =F7-F6 -> 25593.35 | J8: 22 | K8: 1938.01 | L8: depunere | M8: =IF(OR(K8<$O$9,K8>$O$10),"Outlier","În interval") -> În interval | N8: IQR = | O8: =O7-O6 -> 2456.795 | R8: 6 | S8: 22 | T8: 10285.63 | U8: 270.67 | V8: =IF(OR(T8<$Z$9,T8>$Z$10),"Outlier","În interval") -> În interval | W8: =IF(OR(U8<$Z$22,U8>$Z$23),"Outlier","În interval") -> În interval | Y8: IQR = | Z8: =Z7-Z6 -> 22804.603
A9: 5 | B9: 3100.75 | C9: curent | D9: =IF(OR(B9<$F$9,B9>$F$10),"Outlier","În interval") -> În interval | E9: Limita inf. = | F9: =F6-1.5*F8 -> -29182.965 | J9: 23 | K9: 3568.43 | L9: retragere | M9: =IF(OR(K9<$O$9,K9>$O$10),"Outlier","În interval") -> În interval | N9: Limita inf. = | O9: =O6-1.5*O8 -> -2387.7725 | R9: 7 | S9: 23 | T9: 35541.91 | U9: 1269.35 | V9: =IF(OR(T9<$Z$9,T9>$Z$10),"Outlier","În interval") -> În interval | W9: =IF(OR(U9<$Z$22,U9>$Z$23),"Outlier","În interval") -> În interval | Y9: Limită inf. = | Z9: =Z6-1.5*Z8 -> -21681.304
A10: 5 | B10: 8100.5 | C10: economii | D10: =IF(OR(B10<$F$9,B10>$F$10),"Outlier","În interval") -> În interval | E10: Limita sup. = | F10: =F7+1.5*F8 -> 73190.435 | J10: 24 | K10: 3214.61 | L10: retragere | M10: =IF(OR(K10<$O$9,K10>$O$10),"Outlier","În interval") -> În interval | N10: Limita sup. = | O10: =O7+1.5*O8 -> 7439.4075 | R10: 9 | S10: 24 | T10: 6749.45 | U10: 114.4 | V10: =IF(OR(T10<$Z$9,T10>$Z$10),"Outlier","În interval") -> În interval | W10: =IF(OR(U10<$Z$22,U10>$Z$23),"Outlier","În interval") -> În interval | Y10: Limită sup. = | Z10: =Z7+1.5*Z8 -> 69537.106
A11: 6 | B11: 4000 | C11: curent | D11: =IF(OR(B11<$F$9,B11>$F$10),"Outlier","În interval") -> În interval | E11: nr.conturi curente = | F11: =COUNTIF(C2:C198,"curent") -> 96 | J11: 25 | K11: 4123.69 | L11: transfer | M11: =IF(OR(K11<$O$9,K11>$O$10),"Outlier","În interval") -> În interval | N11: nr. Retrageri = | O11: =COUNTIF(L2:L593,"retragere") -> 194 | R11: 9 | S11: 25 | T11: 40572.61 | U11: 3120.97 | V11: =IF(OR(T11<$Z$9,T11>$Z$10),"Outlier","În interval") -> În interval | W11: =IF(OR(U11<$Z$22,U11>$Z$23),"Outlier","În interval") -> În interval
A12: 7 | B12: 3300.25 | C12: curent | D12: =IF(OR(B12<$F$9,B12>$F$10),"Outlier","În interval") -> În interval | E12: nr. cont. ecom. = | F12: =COUNTIF(C2:C198,"economii") -> 101 | J12: 26 | K12: 3876.02 | L12: depunere | M12: =IF(OR(K12<$O$9,K12>$O$10),"Outlier","În interval") -> În interval | N12: nr. Depuneri = | O12: =COUNTIF(L2:L593,"depunere") -> 194 | R12: 9 | S12: 26 | T12: 1025.07 | U12: 19.71 | V12: =IF(OR(T12<$Z$9,T12>$Z$10),"Outlier","În interval") -> În interval | W12: =IF(OR(U12<$Z$22,U12>$Z$23),"Outlier","În interval") -> În interval
A13: 8 | B13: 9200 | C13: economii | D13: =IF(OR(B13<$F$9,B13>$F$10),"Outlier","În interval") -> În interval | E13: total = | F13: =SUM(F11:F12) -> 197 | J13: 27 | K13: 2598.8 | L13: transfer | M13: =IF(OR(K13<$O$9,K13>$O$10),"Outlier","În interval") -> În interval | N13: nr. Transferuri = | O13: =COUNTIF(L2:L593,"transfer") -> 204 | R13: 12 | S13: 27 | T13: 7018.97 | U13: 123.14 | V13: =IF(OR(T13<$Z$9,T13>$Z$10),"Outlier","În interval") -> În interval | W13: =IF(OR(U13<$Z$22,U13>$Z$23),"Outlier","În interval") -> În interval
A14: 9 | B14: 500 | C14: curent | D14: =IF(OR(B14<$F$9,B14>$F$10),"Outlier","În interval") -> În interval | J14: 28 | K14: 2497.72 | L14: depunere | M14: =IF(OR(K14<$O$9,K14>$O$10),"Outlier","În interval") -> În interval | N14: total = | O14: =SUM(O11:O13) -> 592 | R14: 12 | S14: 28 | T14: 34078.37 | U14: 2434.17 | V14: =IF(OR(T14<$Z$9,T14>$Z$10),"Outlier","În interval") -> În interval | W14: =IF(OR(U14<$Z$22,U14>$Z$23),"Outlier","În interval") -> În interval | Y14: min rată = | Z14: =MIN(U2:U139) -> 19.71
A15: 10 | B15: 750 | C15: curent | D15: =IF(OR(B15<$F$9,B15>$F$10),"Outlier","În interval") -> În interval | J15: 29 | K15: 374.46 | L15: depunere | M15: =IF(OR(K15<$O$9,K15>$O$10),"Outlier","În interval") -> În interval | R15: 13 | S15: 29 | T15: 48202.63 | U15: 1928.11 | V15: =IF(OR(T15<$Z$9,T15>$Z$10),"Outlier","În interval") -> În interval | W15: =IF(OR(U15<$Z$22,U15>$Z$23),"Outlier","În interval") -> În interval | Y15: max rată = | Z15: =MAX(T2:T139) -> 49703.15
A16: 10 | B16: 2500 | C16: economii | D16: =IF(OR(B16<$F$9,B16>$F$10),"Outlier","În interval") -> În interval | J16: 30 | K16: 1553.21 | L16: transfer | M16: =IF(OR(K16<$O$9,K16>$O$10),"Outlier","În interval") -> În interval | R16: 14 | S16: 30 | T16: 14580.01 | U16: 275.09 | V16: =IF(OR(T16<$Z$9,T16>$Z$10),"Outlier","În interval") -> În interval | W16: =IF(OR(U16<$Z$22,U16>$Z$23),"Outlier","În interval") -> În interval | Y16: media rată = | Z16: =AVERAGE(T2:T139) -> 24876.358
A17: 16 | B17: 13457.31 | C17: economii | D17: =IF(OR(B17<$F$9,B17>$F$10),"Outlier","În interval") -> În interval | J17: 31 | K17: 2855.63 | L17: transfer | M17: =IF(OR(K17<$O$9,K17>$O$10),"Outlier","În interval") -> În interval | R17: 15 | S17: 31 | T17: 20066.26 | U17: 364.84 | V17: =IF(OR(T17<$Z$9,T17>$Z$10),"Outlier","În interval") -> În interval | W17: =IF(OR(U17<$Z$22,U17>$Z$23),"Outlier","În interval") -> În interval | Y17: mediana rată = | Z17: =MEDIAN(T2:T139) -> 25030.06
A18: 16 | B18: 10362.58 | C18: economii | D18: =IF(OR(B18<$F$9,B18>$F$10),"Outlier","În interval") -> În interval | J18: 32 | K18: 4578.99 | L18: transfer | M18: =IF(OR(K18<$O$9,K18>$O$10),"Outlier","În interval") -> În interval | R18: 17 | S18: 32 | T18: 6434.86 | U18: 321.74 | V18: =IF(OR(T18<$Z$9,T18>$Z$10),"Outlier","În interval") -> În interval | W18: =IF(OR(U18<$Z$22,U18>$Z$23),"Outlier","În interval") -> În interval | Y18: sd. rată = | Z18: =STDEV(T2:T139) -> 14069.623
A19: 16 | B19: 48240.59 | C19: economii | D19: =IF(OR(B19<$F$9,B19>$F$10),"Outlier","În interval") -> În interval | J19: 33 | K19: 3179.09 | L19: retragere | M19: =IF(OR(K19<$O$9,K19>$O$10),"Outlier","În interval") -> În interval | R19: 18 | S19: 33 | T19: 23247.52 | U19: 596.09 | V19: =IF(OR(T19<$Z$9,T19>$Z$10),"Outlier","În interval") -> În interval | W19: =IF(OR(U19<$Z$22,U19>$Z$23),"Outlier","În interval") -> În interval | Y19: Q1 = | Z19: =QUARTILE(T2:T139,1) -> 12525.6
A20: 17 | B20: 6969.16 | C20: economii | D20: =IF(OR(B20<$F$9,B20>$F$10),"Outlier","În interval") -> În interval | J20: 34 | K20: 2303.26 | L20: retragere | M20: =IF(OR(K20<$O$9,K20>$O$10),"Outlier","În interval") -> În interval | R20: 19 | S20: 34 | T20: 26548.52 | U20: 1021.1 | V20: =IF(OR(T20<$Z$9,T20>$Z$10),"Outlier","În interval") -> În interval | W20: =IF(OR(U20<$Z$22,U20>$Z$23),"Outlier","În interval") -> În interval | Y20: Q3 = | Z20: =QUARTILE(T2:T139,3) -> 35330.202
A21: 17 | B21: 15177.94 | C21: economii | D21: =IF(OR(B21<$F$9,B21>$F$10),"Outlier","În interval") -> În interval | J21: 35 | K21: 4936.95 | L21: retragere | M21: =IF(OR(K21<$O$9,K21>$O$10),"Outlier","În interval") -> În interval | R21: 19 | S21: 35 | T21: 34694.49 | U21: 630.81 | V21: =IF(OR(T21<$Z$9,T21>$Z$10),"Outlier","În interval") -> În interval | W21: =IF(OR(U21<$Z$22,U21>$Z$23),"Outlier","În interval") -> În interval | Y21: IQR = | Z21: =Z20-Z19 -> 22804.603
A22: 17 | B22: 30165.8 | C22: economii | D22: =IF(OR(B22<$F$9,B22>$F$10),"Outlier","În interval") -> În interval | J22: 36 | K22: 815.24 | L22: transfer | M22: =IF(OR(K22<$O$9,K22>$O$10),"Outlier","În interval") -> În interval | R22: 20 | S22: 36 | T22: 20331.04 | U22: 390.98 | V22: =IF(OR(T22<$Z$9,T22>$Z$10),"Outlier","În interval") -> În interval | W22: =IF(OR(U22<$Z$22,U22>$Z$23),"Outlier","În interval") -> În interval | Y22: Limită inf. = | Z22: =Z19-1.5*Z21 -> -21681.304
A23: 18 | B23: 47310.37 | C23: curent | D23: =IF(OR(B23<$F$9,B23>$F$10),"Outlier","În interval") -> În interval | J23: 37 | K23: 4548.41 | L23: retragere | M23: =IF(OR(K23<$O$9,K23>$O$10),"Outlier","În interval") -> În interval | R23: 20 | S23: 37 | T23: 39396.71 | U23: 804.01 | V23: =IF(OR(T23<$Z$9,T23>$Z$10),"Outlier","În interval") -> În interval | W23: =IF(OR(U23<$Z$22,U23>$Z$23),"Outlier","În interval") -> În interval | Y23: Limită sup. = | Z23: =Z20+1.5*Z21 -> 69537.106
A24: 19 | B24: 33844.99 | C24: economii | D24: =IF(OR(B24<$F$9,B24>$F$10),"Outlier","În interval") -> În interval | J24: 38 | K24: 648.63 | L24: retragere | M24: =IF(OR(K24<$O$9,K24>$O$10),"Outlier","În interval") -> În interval | R24: 21 | S24: 38 | T24: 42136.68 | U24: 1080.43 | V24: =IF(OR(T24<$Z$9,T24>$Z$10),"Outlier","În interval") -> În interval | W24: =IF(OR(U24<$Z$22,U24>$Z$23),"Outlier","În interval") -> În interval
A25: 20 | B25: 31875.76 | C25: curent | D25: =IF(OR(B25<$F$9,B25>$F$10),"Outlier","În interval") -> În interval | J25: 39 | K25: 473.67 | L25: depunere | M25: =IF(OR(K25<$O$9,K25>$O$10),"Outlier","În interval") -> În interval | R25: 21 | S25: 39 | T25: 3745.17 | U25: 138.71 | V25: =IF(OR(T25<$Z$9,T25>$Z$10),"Outlier","În interval") -> În interval | W25: =IF(OR(U25<$Z$22,U25>$Z$23),"Outlier","În interval") -> În interval
A26: 20 | B26: 8709.94 | C26: curent | D26: =IF(OR(B26<$F$9,B26>$F$10),"Outlier","În interval") -> În interval | J26: 40 | K26: 2700.94 | L26: depunere | M26: =IF(OR(K26<$O$9,K26>$O$10),"Outlier","În interval") -> În interval | R26: 23 | S26: 40 | T26: 31083.07 | U26: 1351.44 | V26: =IF(OR(T26<$Z$9,T26>$Z$10),"Outlier","În interval") -> În interval | W26: =IF(OR(U26<$Z$22,U26>$Z$23),"Outlier","În interval") -> În interval
A27: 20 | B27: 18952.36 | C27: economii | D27: =IF(OR(B27<$F$9,B27>$F$10),"Outlier","În interval") -> În interval | J27: 41 | K27: 3393.6 | L27: transfer | M27: =IF(OR(K27<$O$9,K27>$O$10),"Outlier","În interval") -> În interval | R27: 24 | S27: 41 | T27: 14042.69 | U27: 1003.05 | V27: =IF(OR(T27<$Z$9,T27>$Z$10),"Outlier","În interval") -> În interval | W27: =IF(OR(U27<$Z$22,U27>$Z$23),"Outlier","În interval") -> În interval
A28: 21 | B28: 32719.09 | C28: economii | D28: =IF(OR(B28<$F$9,B28>$F$10),"Outlier","În interval") -> În interval | J28: 42 | K28: 1810.23 | L28: depunere | M28: =IF(OR(K28<$O$9,K28>$O$10),"Outlier","În interval") -> În interval | R28: 25 | S28: 42 | T28: 29379.72 | U28: 587.59 | V28: =IF(OR(T28<$Z$9,T28>$Z$10),"Outlier","În interval") -> În interval | W28: =IF(OR(U28<$Z$22,U28>$Z$23),"Outlier","În interval") -> În interval
A29: 21 | B29: 42633.35 | C29: curent | D29: =IF(OR(B29<$F$9,B29>$F$10),"Outlier","În interval") -> În interval | J29: 43 | K29: 4110.69 | L29: transfer | M29: =IF(OR(K29<$O$9,K29>$O$10),"Outlier","În interval") -> În interval | R29: 26 | S29: 43 | T29: 21060.55 | U29: 915.68 | V29: =IF(OR(T29<$Z$9,T29>$Z$10),"Outlier","În interval") -> În interval | W29: =IF(OR(U29<$Z$22,U29>$Z$23),"Outlier","În interval") -> În interval
A30: 21 | B30: 23959.84 | C30: curent | D30: =IF(OR(B30<$F$9,B30>$F$10),"Outlier","În interval") -> În interval | J30: 44 | K30: 1048.14 | L30: retragere | M30: =IF(OR(K30<$O$9,K30>$O$10),"Outlier","În interval") -> În interval | R30: 26 | S30: 44 | T30: 29597.38 | U30: 896.89 | V30: =IF(OR(T30<$Z$9,T30>$Z$10),"Outlier","În interval") -> În interval | W30: =IF(OR(U30<$Z$22,U30>$Z$23),"Outlier","În interval") -> În interval
A31: 22 | B31: 17031.74 | C31: economii | D31: =IF(OR(B31<$F$9,B31>$F$10),"Outlier","În interval") -> În interval | J31: 45 | K31: 1136.53 | L31: retragere | M31: =IF(OR(K31<$O$9,K31>$O$10),"Outlier","În interval") -> În interval | R31: 27 | S31: 45 | T31: 10460.45 | U31: 197.37 | V31: =IF(OR(T31<$Z$9,T31>$Z$10),"Outlier","În interval") -> În interval | W31: =IF(OR(U31<$Z$22,U31>$Z$23),"Outlier","În interval") -> În interval
A32: 22 | B32: 45876.29 | C32: economii | D32: =IF(OR(B32<$F$9,B32>$F$10),"Outlier","În interval") -> În interval | J32: 46 | K32: 1678.89 | L32: depunere | M32: =IF(OR(K32<$O$9,K32>$O$10),"Outlier","În interval") -> În interval | R32: 28 | S32: 46 | T32: 45075.5 | U32: 959.05 | V32: =IF(OR(T32<$Z$9,T32>$Z$10),"Outlier","În interval") -> În interval | W32: =IF(OR(U32<$Z$22,U32>$Z$23),"Outlier","În interval") -> În interval
A33: 22 | B33: 5798.04 | C33: economii | D33: =IF(OR(B33<$F$9,B33>$F$10),"Outlier","În interval") -> În interval | J33: 47 | K33: 2894.07 | L33: transfer | M33: =IF(OR(K33<$O$9,K33>$O$10),"Outlier","În interval") -> În interval | R33: 28 | S33: 47 | T33: 1998.85 | U33: 43.45 | V33: =IF(OR(T33<$Z$9,T33>$Z$10),"Outlier","În interval") -> În interval | W33: =IF(OR(U33<$Z$22,U33>$Z$23),"Outlier","În interval") -> În interval
A34: 23 | B34: 9691.09 | C34: curent | D34: =IF(OR(B34<$F$9,B34>$F$10),"Outlier","În interval") -> În interval | J34: 48 | K34: 308.23 | L34: transfer | M34: =IF(OR(K34<$O$9,K34>$O$10),"Outlier","În interval") -> În interval | R34: 28 | S34: 48 | T34: 7576.06 | U34: 132.91 | V34: =IF(OR(T34<$Z$9,T34>$Z$10),"Outlier","În interval") -> În interval | W34: =IF(OR(U34<$Z$22,U34>$Z$23),"Outlier","În interval") -> În interval
A35: 23 | B35: 14224.15 | C35: economii | D35: =IF(OR(B35<$F$9,B35>$F$10),"Outlier","În interval") -> În interval | J35: 49 | K35: 1553.44 | L35: depunere | M35: =IF(OR(K35<$O$9,K35>$O$10),"Outlier","În interval") -> În interval | R35: 32 | S35: 49 | T35: 22060.66 | U35: 1225.59 | V35: =IF(OR(T35<$Z$9,T35>$Z$10),"Outlier","În interval") -> În interval | W35: =IF(OR(U35<$Z$22,U35>$Z$23),"Outlier","În interval") -> În interval
... A139: 74 | B139: 28930.59 | C139: economii | D139: =IF(OR(B139<$F$9,B139>$F$10),"Outlier","În interval") -> În interval | J139: 153 | K139: 4894.24 | L139: depunere | M139: =IF(OR(K139<$O$9,K139>$O$10),"Outlier","În interval") -> În interval | R139: 100 | S139: 153 | T139: 39108.3 | U139: 2607.22 | V139: =IF(OR(T139<$Z$9,T139>$Z$10),"Outlier","În interval") -> În interval | W139: =IF(OR(U139<$Z$22,U139>$Z$23),"Outlier","În interval") -> În interval
A140: 74 | B140: 5792.02 | C140: curent | D140: =IF(OR(B140<$F$9,B140>$F$10),"Outlier","În interval") -> În interval | J140: 154 | K140: 1327.68 | L140: retragere | M140: =IF(OR(K140<$O$9,K140>$O$10),"Outlier","În interval") -> În interval
A141: 75 | B141: 24302.57 | C141: curent | D141: =IF(OR(B141<$F$9,B141>$F$10),"Outlier","În interval") -> În interval | J141: 155 | K141: 2555.85 | L141: depunere | M141: =IF(OR(K141<$O$9,K141>$O$10),"Outlier","În interval") -> În interval
A142: 76 | B142: 10214.02 | C142: economii | D142: =IF(OR(B142<$F$9,B142>$F$10),"Outlier","În interval") -> În interval | J142: 156 | K142: 2732.29 | L142: depunere | M142: =IF(OR(K142<$O$9,K142>$O$10),"Outlier","În interval") -> În interval
A143: 77 | B143: 43186.78 | C143: economii | D143: =IF(OR(B143<$F$9,B143>$F$10),"Outlier","În interval") -> În interval | J143: 157 | K143: 791.18 | L143: depunere | M143: =IF(OR(K143<$O$9,K143>$O$10),"Outlier","În interval") -> În interval
...

Sheet PivotTable
B3: Row Labels | C3: Sum of sold | Q3: Values
B4: curent | C4: 2126745.1 | P4: Row Labels | Q4: Sum of suma_credit | R4: Sum of rata_lunara | S4: Count of id_client
B5: economii | C5: 2399962.4 | P5: 1 | Q5: 32875.4 | R5: 1643.77 | S5: 1
B6: Grand Total | C6: 4526707.5 | P6: 2 | Q6: 30066.74 | R6: 812.61 | S6: 1
P7: 4 | Q7: 25006.42 | R7: 1496.38 | S7: 2
P8: 6 | Q8: 20855.24 | R8: 457.68 | S8: 3
P9: 7 | Q9: 35541.91 | R9: 1269.35 | S9: 1
P10: 9 | Q10: 48347.13 | R10: 3255.08 | S10: 3
P11: 12 | Q11: 41097.34 | R11: 2557.31 | S11: 2
P12: 13 | Q12: 48202.63 | R12: 1928.11 | S12: 1
P13: 14 | Q13: 14580.01 | R13: 275.09 | S13: 1
P14: 15 | Q14: 20066.26 | R14: 364.84 | S14: 1
P15: 17 | Q15: 6434.86 | R15: 321.74 | S15: 1
P16: 18 | Q16: 23247.52 | R16: 596.09 | S16: 1
P17: 19 | Q17: 61243.01 | R17: 1651.91 | S17: 2
P18: 20 | Q18: 59727.75 | R18: 1194.99 | S18: 2
... P24: 27 | Q24: 10460.45 | R24: 197.37 | S24: 1
B25: Row Labels | C25: Sum of suma | P25: 28 | Q25: 54650.41 | R25: 1135.41 | S25: 3
B26: depunere | C26: 495869.42 | P26: 32 | Q26: 22060.66 | R26: 1225.59 | S26: 1
B27: retragere | C27: 483425.51 | P27: 33 | Q27: 107784.7 | R27: 4464.4 | S27: 3
B28: transfer | C28: 524234.06 | P28: 34 | Q28: 75431.62 | R28: 1448.79 | S28: 2
B29: Grand Total | C29: 1503529 | P29: 36 | Q29: 67945.45 | R29: 3670.13 | S29: 2
P30: 37 | Q30: 55573.46 | R30: 2628.66 | S30: 2
P31: 39 | Q31: 74644.21 | R31: 2598.23 | S31: 3
P32: 40 | Q32: 56148.06 | R32: 1971.52 | S32: 2
P33: 41 | Q33: 8261.22 | R33: 217.4 | S33: 1
P34: 43 | Q34: 35365.75 | R34: 609.75 | S34: 1
P35: 44 | Q35: 48651.56 | R35: 1013.57 | S35: 1
P36: 45 | Q36: 54505.86 | R36: 1248.12 | S36: 3
P37: 46 | Q37: 50662.97 | R37: 1381.42 | S37: 3
P38: 47 | Q38: 24177.81 | R38: 1364.92 | S38: 2
P39: 48 | Q39: 75332.23 | R39: 3325.73 | S39: 3
P40: 49 | Q40: 36862.26 | R40: 1412.03 | S40: 2
P41: 51 | Q41: 23235.16 | R41: 635.53 | S41: 2
... P80: 100 | Q80: 113794.68 | R80: 6513.27 | S80: 3
P81: Grand Total | Q81: 3432937.4 | R81: 118972.93 | S81: 138

Sheet DashBoard

Sheet TOPSIS
B2: Sold total: 4.526.707
B4: Suma totală a creditelor: 3.432.937
B6: Rata lunară totală: 118.973
B9: Scenariu | C9: Sold total | D9: Suma totală credite | E9: Rată lunară totală | I9: Scenariu | J9: Scor_Performanță | K9: Rank
B10: Actual | C10: 4.526.707 | D10: 3.432.937 | E10: 118.973 | I10: Optimist | J10: 1 | K10: 1
B11: Optimist | C11: 4.979.378 | D11: 3.432.937 | E11: 118.973 | I11: Actual | J11: 0.563 | K11: 2
B12: Pesimist | C12: 4.074.037 | D12: 3.604.584 | E12: 130.87 | I12: Pesimist | J12: 0 | K12: 3
B14: Matricea decizională | I14: Metoda TOPSIS și clasamentul final
